<?xml version="1.0" encoding="utf-8" ?>
<!-- =================================================================================== -->
<!-- |    This document was autogenerated by xacro from /home/rohit/ARM/simulation_ws/src/arm_description/urdf/arm.xacro | -->
<!-- |    EDITING THIS FILE BY HAND IS NOT RECOMMENDED                                 | -->
<!-- =================================================================================== -->
<robot name="arm" xmlns:xacro="http://www.ros.org/wiki/xacro">
    <link name="base_link">
        <visual>
            <origin rpy="0 0 0" xyz="0 0 0.5" />
            <material name="black">
                <color rgba="0 0 0 1" />
            </material>
            <geometry>
                <box size="1 1 1" />
            </geometry>
        </visual>
        <collision>
            <geometry>
                <box size="1 1 1" />
            </geometry>
            <origin rpy="0 0 0" xyz="0 0 0.5" />
        </collision>
        
<inertial>
            <mass value="1" />
            <inertia ixx="1.0" ixy="0.0" ixz="0.0" iyy="1.0" iyz="0.0" izz="1.0" />
        </inertial>

    </link>
    <joint name="base_link__link_01" type="revolute">
        <axis xyz="0 0 1" />
        <limit effort="1000.0" lower="-2.61" upper="1.98" velocity="0.5" />
        <origin rpy="0 0 0" xyz="0 0 1" />
        <parent link="base_link" />
        <child link="link_01" />
    </joint>
    <link name="link_01">
        <visual>
            <origin rpy="0 0 0" xyz="0 0 .15" />
            <material name="yellow">
                <color rgba="1 1 0 1" />
            </material>
            <geometry>
                <cylinder length="0.3" radius="0.25" />
            </geometry>
        </visual>
    </link>
    <joint name="link_01__link_02" type="revolute">
        <axis xyz="0 1 0" />
        <limit effort="1000.0" lower="-1.16" upper="1.9" velocity="0.5" />
        <origin rpy="0 0 0" xyz="0 0 0.3" />
        <parent link="link_01" />
        <child link="link_02" />
    </joint>
    <link name="link_02">
        <visual>
            <origin rpy="0 0 0" xyz="0 0 0.5" />
            <geometry>
                <cylinder length="1" radius="0.15" />
            </geometry>
        </visual>
    </link>
    <joint name="link_02__link_03" type="revolute">
        <axis xyz="0 0 1" />
        <limit effort="1000.0" lower="-2.61" upper="0.71" velocity="0.5" />
        <origin rpy="0 0 0" xyz="0 0 1" />
        <parent link="link_02" />
        <child link="link_03" />
    </joint>
    <link name="link_03">
        <visual>
            <origin rpy="0 0 0" xyz="0 0 0.15" />
            <material name="yellow">
                <color rgba="1 1 0 1" />
            </material>
            <geometry>
                <cylinder length="0.3" radius="0.25" />
            </geometry>
        </visual>
    </link>
    <joint name="link_03__link_04" type="revolute">
        <axis xyz="0 1 0" />
        <limit effort="1000.0" lower="-1.6" upper="1.9" velocity="0.5" />
        <origin rpy="0 0 0" xyz="0 0 0.3" />
        <parent link="link_03" />
        <child link="link_04" />
    </joint>
    <link name="link_04">
        <visual>
            <origin rpy="0 0 0" xyz="0 0 0.4" />
            <geometry>
                <cylinder length="0.8" radius="0.15" />
            </geometry>
        </visual>
    </link>
    <joint name="link_04__link_05" type="revolute">
        <axis xyz="0 1 0" />
        <limit effort="1000.0" lower="1.6" upper="1.97" velocity="0.5" />
        <origin rpy="0 0 0" xyz="0 0 0.8" />
        <parent link="link_04" />
        <child link="link_05" />
    </joint>
    <link name="link_05">
        <visual>
            <origin rpy="0 0 0" xyz="0 0 0.2" />
            <geometry>
                <cylinder length="0.4" radius="0.15" />
            </geometry>
        </visual>
    </link>
    <joint name="link_05__link_06" type="revolute">
        <axis xyz="0 0 1" />
        <limit effort="1000.0" lower="-2.6" upper="2.6" velocity="0.5" />
        <origin rpy="0 0 0" xyz="0 0 0.4" />
        <parent link="link_05" />
        <child link="link_06" />
    </joint>
    <link name="link_06">
        <visual>
            <origin rpy="0 0 0" xyz="0 0 .15" />
            <material name="yellow">
                <color rgba="1 1 0 1" />
            </material>
            <geometry>
                <cylinder length="0.3" radius="0.25" />
            </geometry>
        </visual>
    </link>
    <joint name="link_06__finger_1" type="prismatic">
        <axis xyz="0 1 0" />
        <limit effort="1000.0" lower="0" upper="-0.075" velocity="0.5" />
        <origin rpy="0 0 0" xyz="0 0 0.3" />
        <parent link="link_06" />
        <child link="finger_1" />
    </joint>
    <link name="finger_1">
        <visual>
            <origin rpy="0 0 0" xyz="0 0.125 .15" />
            <material name="green">
                <color rgba="1 0 1 1" />
            </material>
            <geometry>
                <cylinder length="0.3" radius="0.05" />
            </geometry>
        </visual>
    </link>
    <joint name="link_06__finger_2" type="prismatic">
        <axis xyz="0 1 0" />
        <limit effort="1000.0" lower="0" upper="0.075" velocity="0.5" />
        <origin rpy="0 0 0" xyz="0 0 0.3" />
        <parent link="link_06" />
        <child link="finger_2" />
    </joint>
    <link name="finger_2">
        <visual>
            <origin rpy="0 0 0" xyz="0 -0.125 .15" />
            <material name="green">
                <color rgba="1 0 1 1" />
            </material>
            <geometry>
                <cylinder length="0.3" radius="0.05" />
            </geometry>
        </visual>
    </link>
    
<transmission name="trans_base_link__link_01">
        <type>transmission_interface/SimpleTransmission</type>
        <joint name="base_link__link_01">
            <hardwareInterface>hardware_interface/EffortJointInterface</hardwareInterface>
        </joint>
        <actuator name="base_link__link_01_motor">
            <hardwareInterface>hardware_interface/EffortJointInterface</hardwareInterface>
            <mechanicalReduction>1</mechanicalReduction>
        </actuator>
    </transmission>
    <transmission name="trans_link_01__link_02">
        <type>transmission_interface/SimpleTransmission</type>
        <joint name="link_01__link_02">
            <hardwareInterface>hardware_interface/EffortJointInterface</hardwareInterface>
        </joint>
        <actuator name="link_01__link_02_motor">
            <hardwareInterface>hardware_interface/EffortJointInterface</hardwareInterface>
            <mechanicalReduction>1</mechanicalReduction>
        </actuator>
    </transmission>
    <transmission name="trans_link_02__link_03">
        <type>transmission_interface/SimpleTransmission</type>
        <joint name="link_02__link_03">
            <hardwareInterface>hardware_interface/EffortJointInterface</hardwareInterface>
        </joint>
        <actuator name="link_02__link_03_motor">
            <hardwareInterface>hardware_interface/EffortJointInterface</hardwareInterface>
            <mechanicalReduction>1</mechanicalReduction>
        </actuator>
    </transmission>
    <transmission name="trans_link_03__link_04">
        <type>transmission_interface/SimpleTransmission</type>
        <joint name="link_03__link_04">
            <hardwareInterface>hardware_interface/EffortJointInterface</hardwareInterface>
        </joint>
        <actuator name="link_03__link_04_motor">
            <hardwareInterface>hardware_interface/EffortJointInterface</hardwareInterface>
            <mechanicalReduction>1</mechanicalReduction>
        </actuator>
    </transmission>
    <transmission name="trans_link_04__link_05">
        <type>transmission_interface/SimpleTransmission</type>
        <joint name="link_04__link_05">
            <hardwareInterface>hardware_interface/EffortJointInterface</hardwareInterface>
        </joint>
        <actuator name="link_04__link_05_motor">
            <hardwareInterface>hardware_interface/EffortJointInterface</hardwareInterface>
            <mechanicalReduction>1</mechanicalReduction>
        </actuator>
    </transmission>
    <transmission name="trans_link_05__link_06">
        <type>transmission_interface/SimpleTransmission</type>
        <joint name="link_05__link_06">
            <hardwareInterface>hardware_interface/EffortJointInterface</hardwareInterface>
        </joint>
        <actuator name="link_05__link_06_motor">
            <hardwareInterface>hardware_interface/EffortJointInterface</hardwareInterface>
            <mechanicalReduction>1</mechanicalReduction>
        </actuator>
    </transmission>
    <transmission name="trans_link_06__finger_1">
        <type>transmission_interface/SimpleTransmission</type>
        <joint name="link_06__finger_1">
            <hardwareInterface>hardware_interface/EffortJointInterface</hardwareInterface>
        </joint>
        <actuator name="link_06__finger_1_motor">
            <hardwareInterface>hardware_interface/EffortJointInterface</hardwareInterface>
            <mechanicalReduction>1</mechanicalReduction>
        </actuator>
    </transmission>
    <transmission name="trans_link_06__finger_2">
        <type>transmission_interface/SimpleTransmission</type>
        <joint name="link_06__finger_2">
            <hardwareInterface>hardware_interface/EffortJointInterface</hardwareInterface>
        </joint>
        <actuator name="link_06__finger_2_motor">
            <hardwareInterface>hardware_interface/EffortJointInterface</hardwareInterface>
            <mechanicalReduction>1</mechanicalReduction>
        </actuator>
    </transmission>
    <gazebo>
        <plugin name="gazebo_ros_control" filename="libgazebo_ros_control.so">
            <robotNamespace>/arm</robotNamespace>
        </plugin>
    </gazebo>
</robot>

