<?xml version="1.0" ?>
<robot name="arm" xmlns:xacro="http://www.ros.org/wiki/xacro">
    <!-- BGN - Include -->
    <xacro:include filename="$(find arm_description)/urdf/links_joints.xacro"/>
    <!-- END - Include -->
    <!-- BGN - Robot description -->
    <m_link_box name="base_link"
              origin_rpy="0 0 0" origin_xyz="0 0 0"
              mass="1024"
              ixx="170.667" ixy="0" ixz="0"
              iyy="170.667" iyz="0"
              izz="170.667"
              size="1 1 1" />
     <m_joint name="base_link__link_01" type="revolute"
           axis_xyz="0 0 1"
           origin_rpy="0 0 0" origin_xyz="0 0 0.5"
           parent="base_link" child="link_01"
           limit_e="1000" limit_l="-2.61" limit_u="1.98" limit_v="0.5" />
      
     <m_link_cylinder name="link_01"
              origin_rpy="0 0 0" origin_xyz="0 0 0.1"
              mass="157.906"
              ixx="13.235" ixy="0" ixz="0"
              iyy="13.235" iyz="0"
              izz="9.655"
              radius="0.25" length="0.3" />
    <m_joint name="link_01__link_02" type="revolute"
           axis_xyz="0 1 0"
           origin_rpy="0 0 0" origin_xyz="0 0 0.3"
           parent="link_01" child="link_02"
           limit_e="1000" limit_l="-1.61" limit_u="1.9" limit_v="0.5" />
    
     <m_link_cylinder name="link_02"    
              origin_rpy="0 0 0" origin_xyz="0 0 0.3"
              mass="57.906"
              ixx="12.679" ixy="0" ixz="0"
              iyy="12.679" iyz="0"
              izz="0.651"
              radius="0.15" length="1" />
             
     <m_joint name="link_02__link_03" type="revolute"
           axis_xyz="0 0 1"
           origin_rpy="0 0 0" origin_xyz="0 0 0.8"
           parent="link_02" child="link_03"
           limit_e="1000" limit_l="-2.61" limit_u="0.71" limit_v="0.5" />
    <m_link_cylinder name="link_03"    
              origin_rpy="0 0 0" origin_xyz="0 0 0.15"
              mass="57.906"
              ixx="12.679" ixy="0" ixz="0"
              iyy="12.679" iyz="0"
              izz="0.651"
              radius="0.25" length="0.3" />
     <m_joint name="link_03__link_04" type="revolute"
           axis_xyz="0 1 0"
           origin_rpy="0 0 0" origin_xyz="0 0 0.3"
           parent="link_03" child="link_04"
           limit_e="1000" limit_l="-1.61" limit_u="1.9" limit_v="0.5" />                
     <m_link_cylinder name="link_04"    
              origin_rpy="0 0 0" origin_xyz="0 0 0.4"
              mass="57.906"
              ixx="12.679" ixy="0" ixz="0"
              iyy="12.679" iyz="0"
              izz="0.651"
              radius="0.15" length="0.8" />
     <m_joint name="link_04__link_05" type="revolute"
           axis_xyz="0 1 0"
           origin_rpy="0 0 0" origin_xyz="0 0 0.8"
           parent="link_04" child="link_05"
           limit_e="1000" limit_l="1.61" limit_u="1.97" limit_v="0.5" /> 
     <m_link_cylinder name="link_05"    
              origin_rpy="0 0 0" origin_xyz="0 0 0.2"
              mass="18.056"
              ixx=".479" ixy="0" ixz="0"
              iyy="0.479" iyz="0"
              izz="0.651"
              radius="0.15" length="0.4" />     
     <m_joint name="link_05__link_06" type="revolute"
           axis_xyz="0 0 1"
           origin_rpy="0 0 0" origin_xyz="0 0 0.4"
           parent="link_05" child="link_06"
           limit_e="1000" limit_l="-2.6" limit_u="2.6" limit_v="0.5" />   
    <m_link_cylinder name="link_06"    
              origin_rpy="0 0 0" origin_xyz="0 0 0.15"
              mass="18.056"
              ixx="0.479" ixy="0" ixz="0"
              iyy="0.479" iyz="0"
              izz="0.651"
              radius="0.204" length="0.3" /> 
    <joint name="link_06__finger_1" type="prismatic">
        <axis xyz="0 1 0"/>
        <limit effort="1000.0" lower="0" upper="-0.075" velocity="0.5"/>
        <origin rpy="0 0 0" xyz="0 0 0.3"/>
        <parent link="link_06"/>
        <child link="finger_1"/>
        <safety_controller k_position="20" k_velocity="20" soft_lower_limit="${-0.15 }" soft_upper_limit="${ 0.0 }"/>
        <dynamics damping="50" friction="1"/>
    </joint>
    <transmission name="trans_link_06__finger_1">
      <type>transmission_interface/SimpleTransmission</type>
      <joint name="link_06__finger_1">
        <hardwareInterface>hardware_interface/PositionJointInterface</hardwareInterface>
      </joint>
      <actuator name="motor_link_06__finger_1">
        <hardwareInterface>hardware_interface/PositionJointInterface</hardwareInterface>
        <mechanicalReduction>1</mechanicalReduction>
      </actuator>
    </transmission>
    <m_link_cylinder name="finger_1"    
              origin_rpy="0 0 0" origin_xyz="0 0.125 0.15"
              mass="5.906"
              ixx="12.679" ixy="0" ixz="0"
              iyy="12.679" iyz="0"
              izz="0.651"
              radius="0.05" length="0.3" />
    <joint name="link_06__finger_2" type="prismatic">
        <axis xyz="0 1 0"/>
        <limit effort="1000.0" lower="0" upper="0.075" velocity="0.5"/>
        <origin rpy="0 0 0" xyz="0 0 0.3"/>
        <parent link="link_06"/>
        <child link="finger_2"/>
        <safety_controller k_position="20" k_velocity="20" soft_lower_limit="${-0.15 }" soft_upper_limit="${ 0.0 }"/>
        <dynamics damping="50" friction="1"/>
    </joint>
    <transmission name="trans_link_06__finger_2">
      <type>transmission_interface/SimpleTransmission</type>
      <joint name="link_06__finger_2">
        <hardwareInterface>hardware_interface/PositionJointInterface</hardwareInterface>
      </joint>
      <actuator name="motor_link_06__finger_2">
        <hardwareInterface>hardware_interface/PositionJointInterface</hardwareInterface>
        <mechanicalReduction>1</mechanicalReduction>
      </actuator>
    </transmission>
      <m_link_cylinder name="finger_2"    
              origin_rpy="0 0 0" origin_xyz="0 -0.125 0.15"
              mass="5.906"
              ixx="12.679" ixy="0" ixz="0"
              iyy="12.679" iyz="0"
              izz="0.651"
              radius="0.05" length="0.3" />
  
    <!-- END - Robot description -->

<gazebo>
        <plugin name="gazebo_ros_control" filename="libgazebo_ros_control.so">
            <robotNamespace>/arm</robotNamespace>
        </plugin>
    </gazebo>
</robot>